<?xml version="1.0"?>
<!--
    文件：wheel.urdf.xacro
    功能：定义 wheel 的 xacro 宏
    作者：hzy
    日期：2025-07-11
-->
<robot name="fishbot" xmlns:xacro="http://ros.org/wiki/xacro">
   <xacro:include filename="$(find fishbot_description)/urdf/fishbot/common_inertia.xacro" />
    <!--
        宏：wheel_xacro
        参数：${wheel_name}, xyz
        功能：生成 wheel link 及其与 base_link 的固定 joint
    -->
    <xacro:macro name="wheel_xacro" params="wheel_name xyz">
        <!-- 定义 {wheel_name} link -->
        <link name="${wheel_name}_link">
            <visual>
                <origin xyz="0.0 0.0 0.0" rpy="1.57097 0.0 0.0"/>
                <geometry>
                    <cylinder radius="0.032" length="0.04"/>
                </geometry>
                <material name="yellow">
                    <color rgba="1.0 1.0 0.0 0.8"/>
                </material>
            </visual>
            <collision>
                <origin xyz="0.0 0.0 0.0" rpy="1.57097 0.0 0.0"/>
                <geometry>
                    <cylinder radius="0.032" length="0.04"/>
                </geometry>
                <material name="yellow">
                    <color rgba="1.0 1.0 0.0 0.8"/>
                </material>
            </collision>
            <xacro:cylinder_inertia m="0.1" h="0.04" r="0.032"/>
        </link>

        <!-- 定义 wheel 与 base_link 的固定 joint -->
        <joint name="${wheel_name}_joint" type="continuous">
            <parent link="base_link"/>
            <child link="${wheel_name}_link"/>
            <origin xyz="${xyz}" rpy="0.0 0.0 0.0"/>
            <axis xyz="0.0 1.0 0.0"/>
        </joint>

        <gazebo reference="${wheel_name}_link">
            <material>Gazebo/Black</material>
            <mu1 value="20.0" />
            <mu2 value="20.0" />
            <kp value="1000000000.0" />
            <kd value="1.0" />
        </gazebo>
    </xacro:macro>
</robot>
